Workbook
Name adiposo: 'HOJA DE TRABAJO'!#REF!
Name adiposo_muscular: 'HOJA DE TRABAJO'!#REF!
Name AF: 'HOJA DE TRABAJO'!#REF!
Name arq: '[1]Proc datos brutos'!$AH$3:$AJ$48
Name defcen: '[1]Proc datos brutos'!$AK$3:$AM$48
Name deflat: '[1]Proc datos brutos'!$AN$3:$AP$48
Name delcen: '[1]Proc datos brutos'!$AZ$3:$BB$48
Name dellat: '[1]Proc datos brutos'!$AW$3:$AY$48
Name depf: 'HOJA DE TRABAJO'!#REF!
Name depm: 'HOJA DE TRABAJO'!#REF!
Name deps: 'HOJA DE TRABAJO'!#REF!
Name meddef: '[1]Proc datos brutos'!$AQ$3:$AS$48
Name medof: '[1]Proc datos brutos'!$AT$3:$AV$48
Name muscular: 'HOJA DE TRABAJO'!#REF!
Name muscular_osea: 'HOJA DE TRABAJO'!#REF!
Name posiciones: '[1]Proc datos brutos'!$BD$2:$BF$8

Sheet HOJA DE TRABAJO
A2: Nombre: | B2: Leandro Ceballos | G2: Sexo (m=1;f=2): | I2: 2
A3: Fecha: | B3: 44664 | C3: Fecha de Nac. | E3: 21/10/1893 | G3: Edad decimal: | I3: 38
A4: Variable | B4: serie 1 | C4: serie 2 | D4: serie 3 | E4: serie 4 | F4: serie 5 | G4: mediana
A5: DATOS BÁSICOS
A6: Peso Bruto (Kg) | B6: 65.6 | G6: =ROUND(MEDIAN(B6:F6),3) -> 65.6
A7: Talla Corporal (cm) | B7: 168 | G7: =ROUND(MEDIAN(B7:F7),3) -> 168
A8: DIÁMETROS (cm)
A9: Humeral (biepicondilar) | B9: 6 | G9: =ROUND(MEDIAN(B9:F9),3) -> 6
A10: Femoral (biepicondilar) | B10: 10.3 | G10: =ROUND(MEDIAN(B10:F10),3) -> 10.3
A11: PERÍMETROS (cm)
A12: Brazo Relajado | B12: 28 | G12: =ROUND(MEDIAN(B12:F12),3) -> 28
A13: Brazo Flexionado en Tensión | B13: 30 | G13: =ROUND(MEDIAN(B13:F13),3) -> 30
A14: Cintura (mínima) | B14: 72.5 | G14: =ROUND(MEDIAN(B14:F14),3) -> 72.5
A15: Cadera (máximo) | B15: 93.3 | G15: =ROUND(MEDIAN(B15:F15),3) -> 93.3
A16: Pantorrilla (máxima) | B16: 34.5 | G16: =ROUND(MEDIAN(B16:F16),3) -> 34.5
A17: PLIEGUES CUTÁNEOS (mm)
A18: Tríceps | B18: 8 | C18: 7.5 | G18: =ROUND(MEDIAN(B18:F18),3) -> 7.75
A19: Subescapular | B19: 5.5 | C19: 5 | G19: =ROUND(MEDIAN(B19:F19),3) -> 5.25
A20: Bíceps | B20: 1.5 | C20: 1.5 | G20: =ROUND(MEDIAN(B20:F20),3) -> 1.5
A21: Cresta ilíaca | B21: 7.2 | C21: 7 | G21: =ROUND(MEDIAN(B21:F21),3) -> 7.1
A22: Supraespinal | B22: 4.5 | C22: 4.5 | G22: =ROUND(MEDIAN(B22:F22),3) -> 4.5
A23: Abdominal | B23: 13 | C23: 13 | G23: =ROUND(MEDIAN(B23:F23),3) -> 13
A24: Muslo Medial | B24: 14 | C24: 14 | G24: =ROUND(MEDIAN(B24:F24),3) -> 14
A25: Pantorrilla (máxima) | B25: 6 | C25: 6 | G25: =ROUND(MEDIAN(B25:F25),3) -> 6
A27: NO IMPRIMIR ESTA HOJA
A28: Somatotipo de Heath & Carter (1990)
A30: Endomorphy | B30: =(-0.7182+(0.1451*B31)-(0.00068*B31^2)+(0.0000014*B31^3)) -> 1.6481092
A31: Sum SF | B31: =SUM(G18+G22+G19)*170.18/$G$7 -> 17.727083
A33: Mesomorphy | B33: =(0.858*G9)+(0.601*G10)+(0.188*(G13-G18/10))+(0.161*(G16-G25/10))-(G7*0.131)+4.5 -> 4.7825
A35: Ectomorphy | B35: =IF(B36>=40.75,0.732*B36-28.58,0.463*B36-17.63) -> 1.9162411
A36: HWR | B36: =G7/(G6)^0.3333 -> 41.661532
A38: comp corporal | C38: densidad
A39: D&W | C39: masc | D39: fem
A40: suma 4p | B40: =B18+B19+B20+B21 -> 22.2
A41: log suma 4p | B41: =LOG(B40) -> 1.346353 | C41: =1.1765-(0.0744*B41) -> 1.0763313 | D41: =1.1567-(0.0717*B41) -> 1.0601665
A42: %graso | C42: =(495/C41)-450 -> 9.8955565 | D42: =(495/D41)-450 -> 16.907796
A43: Yuhasz
A44: suma 6 p | B44: =B18+B19+B22+B23+B24+B25 -> 51 | C44: =(0.1051*B44)+2.585 -> 7.9451 | D44: =(0.1548*B44)+3.58 -> 11.4748
A46: AMB | B46: =(B12*10-(B18*3.14))^2/(4*3.14) -> 5172.2782
B47: =(B12-(B18*0.314))^2/(4*3.14) -> 51.722782

Sheet INFORME IMPRIMIR
A1: Informe de Composición Corporal Nivel 1 | I1: Lic. Sonia Polidori NUTRICION DEPORTIVA Teléfono: 3514598393 E-mail: sonipoli@hotmail.com
C3: Nombre: | D3: ='HOJA DE TRABAJO'!B2 -> Leandro Ceballos | H3: Edad: | I3: ='HOJA DE TRABAJO'!I3 -> 38
C5: Número de medición: | E5: 1 | F5: Fecha de medición: | H5: ='HOJA DE TRABAJO'!B3 -> 44664
E8: Resultados | F8: Valor Ajustado | L8: EJES
B10: Peso (kg) | E10: 65.6 | L10: 3 | M10: 2
B11: Talla (cm) | E11: 178
B12: Humeral (biepicondilar) | E12: ='HOJA DE TRABAJO'!G9 -> 6 | L12: 2 | M12: 1
B13: Femoral (biepicondilar) | E13: ='HOJA DE TRABAJO'!G10 -> 10.3
B14: Brazo Relajado | E14: ='HOJA DE TRABAJO'!G12 -> 28 | M14: 6
B15: Brazo Flexionado en Tensión | E15: ='HOJA DE TRABAJO'!G13 -> 30 | M15: 5
B16: Cintura (mínima) | E16: ='HOJA DE TRABAJO'!G14 -> 72.5 | M16: 4
B17: Caderas (máxima) | E17: ='HOJA DE TRABAJO'!G15 -> 93.3 | M17: 3
B18: Pantorrilla (máxima) | E18: ='HOJA DE TRABAJO'!G16 -> 34.5 | M18: 2
B19: Tríceps | E19: ='HOJA DE TRABAJO'!G18 -> 7.75 | M19: 1
B20: Subescapular | E20: ='HOJA DE TRABAJO'!G19 -> 5.25
B21: Bíceps | E21: ='HOJA DE TRABAJO'!G20 -> 1.5 | M21: 10
B22: Cresta Ilíaca | E22: ='HOJA DE TRABAJO'!G21 -> 7.1 | M22: 9
B23: Supraespinal | E23: ='HOJA DE TRABAJO'!G22 -> 4.5 | M23: 8
B24: Abdominal | E24: ='HOJA DE TRABAJO'!G23 -> 13 | L24: 9 | M24: 7
B25: Muslo (medial) | E25: ='HOJA DE TRABAJO'!G24 -> 14 | L25: 8 | M25: 6
B26: Pantorrilla | E26: ='HOJA DE TRABAJO'!G25 -> 6 | L26: 7 | M26: 5
M27: 6
B28: Índices y composición corporal (Durnin & Womersley)
B29: IMC | C29: kg/m-2 | E29: =E10/(E11*0.01)^2 -> 20.704457 | L29: 14 | M29: 5
B30: IndCint/Cad | E30: =E16/E17 -> 0.77706324
B31: Suma 6 pl | C31: mm | E31: =E19+E20+E23+E24+E25+E26 -> 50.5
B32: % graso | C32: Durnin & W | E32: =IF('HOJA DE TRABAJO'!I2=1,+'HOJA DE TRABAJO'!C42,+'HOJA DE TRABAJO'!D42) -> 16.907796 | M32: 4
B33: Grasa | C33: kg | E33: =E10*E32/100 -> 11.091514 | L33: 12 | M33: 3
B34: Magra | C34: kg | E34: =E10-E33 -> 54.508486 | L34: 10 | M34: 2
M35: 1
B36: % graso | C36: Yuhasz (atletas) | E36: =IF('HOJA DE TRABAJO'!I2=1,+'HOJA DE TRABAJO'!C44,+'HOJA DE TRABAJO'!D44) -> 11.4748 | L36: 7
B37: Grasa | C37: kg | E37: =E10*E36/100 -> 7.5274688 | L37: 6
B38: Magra | C38: kg | E38: =E10-E37 -> 58.072531 | L38: 5
L39: 4
B40: Area Musc Brazo mm2 | E40: ='HOJA DE TRABAJO'!B46 -> 5172.2782 | L40: 3
L41: 2
A44: Somatotipo de Heath & Carter (1990) | I44: Francis Holway NUTRICION DEPORTIVA Teléfono: 4822-9436 E-mail: fholway@hotmail.com
C46: Nombre: | D46: ='HOJA DE TRABAJO'!B2 -> Leandro Ceballos | H46: Edad: | I46: ='HOJA DE TRABAJO'!I3 -> 38
C48: Número de medición: | E48: ='HOJA DE TRABAJO'!I1 -> 0 | F48: Fecha de medición: | H48: ='HOJA DE TRABAJO'!B3 -> 44664
A50: Sumatoria de pliegues: | C50: =SUM(E19,E20,E23) -> 17.5 | D50: per.correg. brazo: | F50: =E15-E19/10 -> 29.225 | G50: raíz cúbica del peso: | I50: =E10^0.33333 -> 4.0330031
...

Sheet CALCULO PESO IDEAL
F1: Objetivo % graso | G1: Peso y composición ideal | H1: Cantidad de grasa a bajar Kg
B2: Peso | C2: Kg | E2: ='INFORME IMPRIMIR'!E10 -> 65.6 | G2: =(E5*100/(100-F3)) -> 54.508486
B3: % graso | C3: Durnin & W | E3: ='INFORME IMPRIMIR'!E32 -> 16.907796
B4: Grasa | C4: kg | E4: ='INFORME IMPRIMIR'!E33 -> 11.091514 | G4: =G2*F3*0.01 -> 0 | H4: =+E4-G4 -> 11.091514
B5: Magra | C5: kg | E5: ='INFORME IMPRIMIR'!E34 -> 54.508486 | G5: =E5 -> 54.508486
B7: Peso | C7: Kg | E7: ='INFORME IMPRIMIR'!E10 -> 65.6 | G7: =(E10*100/(100-F8)) -> 58.072531
B8: % graso | C8: Yuhasz (atletas) | E8: ='INFORME IMPRIMIR'!E36 -> 11.4748
B9: Grasa | C9: kg | E9: ='INFORME IMPRIMIR'!E37 -> 7.5274688 | G9: =G7*F8*0.01 -> 0 | H9: =+E9-G9 -> 7.5274688
B10: Magra | C10: kg | E10: ='INFORME IMPRIMIR'!E38 -> 58.072531 | G10: =E10 -> 58.072531
